<?xml version="1.0" ?>
<robot name="meca" xmlns:xacro="http://www.ros.org/wiki/xacro" >
    <!-- STEP 1 - Gazebo PLugin -->
  <xacro:include filename="$(find spawn_urdf_ros2)/urdf/meca.gazebo" /> <!-- Replace with your Gazebo File -->
        
    <!-- STEP 2 - RViz colors -->
    
  <!-- STEP 3 - RViz colors -->

  <link name="base_footprint"></link>
  <!-- STEP 2 - Robot chassis = base_link -->
  
  <joint name="base_footprint_joint" type="fixed">
  <origin xyz="0 0 0" rpy="0 0 0" />
  <parent link="base_footprint"/>
  <child link="base_link" />
  </joint>
    
      
  <link name="base_link"> 
    <inertial>
      <origin xyz="0.0011688245966463109 -1.2767527127815893e-12 0.07427866223177358" rpy="0 0 0"/>
      <mass value="46.93785531922561"/>
      <inertia ixx="0.193981" iyy="0.387085" izz="0.499531" ixy="-0.0" iyz="0.0" ixz="-0.000492"/>
    </inertial>
    <visual>
      <origin xyz="0 0 0" rpy="0 0 0"/>
      <geometry>
        <mesh filename="package://spawn_urdf_ros2/meshes/base_link.stl" scale="0.001 0.001 0.001"/>
      </geometry>
          <material name="orange"/> 
    </visual>
    <collision>
      <origin xyz="0 0 0" rpy="0 0 0"/>
      <geometry>
        <mesh filename="package://spawn_urdf_ros2/meshes/base_link.stl" scale="0.001 0.001 0.001"/>
      </geometry>
    </collision>
  </link>

 

  <link name="left_wheel_1">
    <inertial>
      <origin xyz="7.848152248320844e-14 -0.02199999999999984 0.0" rpy="0 0 0"/>
      <mass value="3.329302814641776"/>
      <inertia ixx="0.005265" iyy="0.010113" izz="0.005265" ixy="0.0" iyz="0.0" ixz="-0.0"/>
    </inertial>
    <visual>
      <origin xyz="-0.0 0.1 -0.075" rpy="0 0 0"/>
      <geometry>
        <mesh filename="package://spawn_urdf_ros2/meshes/left_wheel_1.stl" scale="0.001 0.001 0.001"/>
      </geometry>
  <material name="green"/> 
    </visual>
    <collision>
      <origin xyz="-0.0 0.1 -0.075" rpy="0 0 0"/>
      <geometry>
        <mesh filename="package://spawn_urdf_ros2/meshes/left_wheel_1.stl" scale="0.001 0.001 0.001"/>
      </geometry>
    </collision>
  </link>

  <link name="right_wheel_1">
    <inertial>
      <origin xyz="-7.847430603354844e-14 0.02200000000000006 0.0" rpy="0 0 0"/>
      <mass value="3.329302814641776"/>
      <inertia ixx="0.005265" iyy="0.010113" izz="0.005265" ixy="0.0" iyz="0.0" ixz="0.0"/>
    </inertial>
    <visual>
      <origin xyz="0.0 -0.1 -0.075" rpy="0 0 0"/>
      <geometry>
        <mesh filename="package://spawn_urdf_ros2/meshes/right_wheel_1.stl" scale="0.001 0.001 0.001"/>
      </geometry>
   <material name="green"/> 
    </visual>
    <collision>
      <origin xyz="0.0 -0.1 -0.075" rpy="0 0 0"/>
      <geometry>
        <mesh filename="package://spawn_urdf_ros2/meshes/right_wheel_1.stl" scale="0.001 0.001 0.001"/>
      </geometry>
    </collision>
  </link>

  <link name="lidar_v1_1">
    <inertial>
      <origin xyz="5.828670879282075e-18 6.217248937900875e-17 0.02737438134945505" rpy="0 0 0"/>
      <mass value="2.1599229360390186"/>
      <inertia ixx="0.0014" iyy="0.0014" izz="0.001721" ixy="0.0" iyz="-0.0" ixz="0.0"/>
    </inertial>
    <visual>
      <origin xyz="-0.0 -0.0 -0.125" rpy="0 0 0"/>
      <geometry>
        <mesh filename="package://spawn_urdf_ros2/meshes/lidar_v1_1.stl" scale="0.001 0.001 0.001"/>
      </geometry>
       <material name="blue"/> 
    </visual>
    <collision>
      <origin xyz="-0.0 -0.0 -0.125" rpy="0 0 0"/>
      <geometry>
        <mesh filename="package://spawn_urdf_ros2/meshes/lidar_v1_1.stl" scale="0.001 0.001 0.001"/>
      </geometry>
    </collision>
  </link>

  <joint name="joint_left" type="continuous">
    <origin xyz="0.0 -0.1 0.075" rpy="0 0 0"/>
    <parent link="base_link"/>
    <child link="left_wheel_1"/>
    <axis xyz="0.0 1.0 0.0"/>
  </joint>

  <joint name="joint_right" type="continuous">
    <origin xyz="0.0 0.1 0.075" rpy="0 0 0"/>
    <parent link="base_link"/>
    <child link="right_wheel_1"/>
    <axis xyz="0.0 1.0 0.0"/>
  </joint>

  <joint name="joint_lidar" type="fixed">
    <origin xyz="0.0 0.0 0.125" rpy="0 0 0"/>
    <parent link="base_link"/>
    <child link="lidar_v1_1"/>
    <axis xyz="-0.0 0.0 1.0"/>
  </joint>
   
  <gazebo reference="left_wheel_1">
      <mu1>0.2</mu1>
      <mu2>0.2</mu2>
      <kp>1000000.0</kp>
      <kd>100.0</kd>
      <minDepth>0.0001</minDepth>
      <maxVel>1.0</maxVel>
  </gazebo>

  <gazebo reference="right_wheel_1">
      <mu1>0.2</mu1>
      <mu2>0.2</mu2>
      <kp>1000000.0</kp>
      <kd>100.0</kd>
      <minDepth>0.0001</minDepth>
      <maxVel>1.0</maxVel>
  </gazebo>

    <gazebo reference="base_link">
      <mu1>0.000002</mu1>
      <mu2>0.000002</mu2>
    </gazebo>

</robot>